Workbook

Sheet 2569
K1: แบบฟอร์ม 3.1(1)
A2: บันทึกปริมาณการใช้กระดาษ
A3: เดือน | B3: ปริมาณการใช้กระดาษปี 2568 | F3: ปริมาณการใช้กระดาษปี 2569 | J3: ร้อยละปริมาณการใช้กระดาษ
B4: จำนวนคน | C4: (รีม)ปี2568 | D4: ค่ากระดาษ/เดือน (บาท) | E4: (รีม/คน) ปี2568 | F4: จำนวนคน | G4: (รีม) ปี 2569 | H4: ค่ากระดาษ/เดือน (บาท) | I4: (รีม/คน) ปี 2569 | J4: (รีม)ปี2569 | K4: (รีม/คน)ปี2569
A5: ม.ค. | B5: ='[1]2568'!F5 -> 95 | C5: ='[1]2568'!G5 -> 194.4 | D5: ='[1]2568'!H5 -> 8352 | E5: =C5/B5 -> 2.0463158 | F5: 94 | I5: =G5/F5 -> 0 | J5: =(G5-C5)/C5 -> -1 | K5: =(I5-E5)/E5 -> -1
A6: ก.พ. | B6: ='[1]2568'!F6 -> 95 | C6: ='[1]2568'!G6 -> 175.5 | D6: ='[1]2568'!H6 -> 7540 | E6: =C6/B6 -> 1.8473684 | F6: 94 | I6: - | J6: =(G6-C6)/C6 -> -1 | K6: =(I6-E6)/E6 -> #VALUE!
A7: มี.ค. | B7: ='[1]2568'!F7 -> 95 | C7: ='[1]2568'!G7 -> 245.7 | D7: ='[1]2568'!H7 -> 10556 | E7: =C7/B7 -> 2.5863158 | F7: 94 | I7: =G7/F7 -> 0 | J7: =(G7-C7)/C7 -> -1 | K7: =(I7-E7)/E7 -> -1
A8: เม.ย. | B8: ='[1]2568'!F8 -> 95 | C8: ='[1]2568'!G8 -> 189 | D8: ='[1]2568'!H8 -> 8120 | E8: =C8/B8 -> 1.9894737 | F8: 94 | I8: =G8/F8 -> 0 | J8: =(G8-C8)/C8 -> -1 | K8: =(I8-E8)/E8 -> -1
A9: พ.ค. | B9: ='[1]2568'!F9 -> 95 | C9: ='[1]2568'!G9 -> 126.9 | D9: ='[1]2568'!H9 -> 5452 | E9: =C9/B9 -> 1.3357895 | F9: 94 | I9: =G9/F9 -> 0 | J9: =(G9-C9)/C9 -> -1 | K9: =(I9-E9)/E9 -> -1
A10: มิ.ย. | B10: ='[1]2568'!F10 -> 95 | C10: ='[1]2568'!G10 -> 183.6 | D10: ='[1]2568'!H10 -> 7888 | E10: =C10/B10 -> 1.9326316 | F10: 94 | I10: =G10/F10 -> 0 | J10: =(G10-C10)/C10 -> -1 | K10: =(I10-E10)/E10 -> -1
A11: ก.ค. | B11: ='[1]2568'!F11 -> 95 | C11: ='[1]2568'!G11 -> 159.3 | D11: ='[1]2568'!H11 -> 6844 | E11: =C11/B11 -> 1.6768421 | F11: 94 | I11: =G11/F11 -> 0 | J11: =(G11-C11)/C11 -> -1 | K11: =(I11-E11)/E11 -> -1
A12: ส.ค. | B12: ='[1]2568'!F12 -> 95 | C12: ='[1]2568'!G12 -> 206.55 | D12: ='[1]2568'!H12 -> 8874 | E12: =C12/B12 -> 2.1742105 | F12: 94 | I12: =G12/F12 -> 0 | J12: =(G12-C12)/C12 -> -1 | K12: =(I12-E12)/E12 -> -1
A13: ก.ย. | B13: ='[1]2568'!F13 -> 95 | C13: ='[1]2568'!G13 -> 198.45 | D13: ='[1]2568'!H13 -> 8526 | E13: =C13/B13 -> 2.0889474 | F13: 94 | I13: =G13/F13 -> 0 | J13: =(G13-C13)/C13 -> -1 | K13: =(I13-E13)/E13 -> -1
A14: ต.ค. | B14: ='[1]2568'!F14 -> 95 | C14: ='[1]2568'!G14 -> 140.4 | D14: ='[1]2568'!H14 -> 6032 | E14: =C14/B14 -> 1.4778947 | F14: 94 | I14: =G14/F14 -> 0 | J14: =(G14-C14)/C14 -> -1 | K14: =(I14-E14)/E14 -> -1
A15: พ.ย. | B15: ='[1]2568'!F15 -> 95 | C15: ='[1]2568'!G15 -> 213.3 | D15: ='[1]2568'!H15 -> 9164 | E15: =C15/B15 -> 2.2452632 | F15: 94 | I15: =G15/F15 -> 0 | J15: =(G15-C15)/C15 -> -1 | K15: =(I15-E15)/E15 -> -1
A16: ธ.ค. | B16: ='[1]2568'!F16 -> 95 | C16: ='[1]2568'!G16 -> 164.7 | D16: ='[1]2568'!H16 -> 7076 | E16: =C16/B16 -> 1.7336842 | F16: 94 | I16: =G16/F16 -> 0 | J16: =(G16-C16)/C16 -> -1 | K16: =(I16-E16)/E16 -> -1
A17: เฉลี่ย | B17: =AVERAGE(B5:B16) -> 95 | C17: =AVERAGE(C5:C16) -> 183.15 | D17: =AVERAGE(D5:D16) -> 7868.6667 | E17: =AVERAGE(E5:E16) -> 1.9278947 | F17: =AVERAGE(F5:F16) -> 94 | G17: =AVERAGE(G5:G16) -> #DIV/0! | H17: =AVERAGE(H5:H16) -> #DIV/0! | I17: =G17/F17 -> #DIV/0! | J17: =(G17-C17)/C17 -> #DIV/0! | K17: =(I17-E17)/E17 -> #DIV/0!
A18: รวม | B18: =SUM(B5:B16) -> 1140 | C18: =SUM(C5:C16) -> 2197.8 | D18: =SUM(D5:D16) -> 94424 | E18: =SUM(E5:E16) -> 23.134737 | F18: =SUM(F5:F16) -> 1128 | G18: =SUM(G5:G16) -> 0 | H18: =SUM(H5:H16) -> 0 | I18: =SUM(I5:I16) -> 0 | J18: =(G18-C18)/C18 -> -1 | K18: =(I18-E18)/E18 -> -1
A43: สรุปปริมาณการใช้กระดาษ 1. การปริมาณกระดาษสะสมตั้งแต่เดือน มกราคม ถึง ….............ปี 2569 เท่ากับ …......... รีม ลดลงจาก ปี 25….ในช่วงเวลาเดียวกัน เท่ากับ …............. รีม คิดเป็น …...... % 2. การปริมาณกระดาษต่อคนสะสมตั้งแต่เดือน มกราคม ถึง ….............ปี 2569 เท่ากับ …......... รีม/คน ลดลงจาก ปี 25….ในช่วงเวลาเดียวกัน เท่ากับ …......... รีม/คน คิดเป็น …...... % 3. การปริมาณกระดาษเฉลี่ยตั้งแต่เดือน มกราคม ถึง ….............ปี 2569 เท่ากับ …......... รีม ลดลงจาก ปี 25….ในช่วงเวลาเดียวกัน เท่ากับ …............. รีม คิดเป็น …...... % 4. การปริมาณกระดาษต่อคนเฉลี่ยตั้งแต่เดือน มกราคม ถึง ….............ปี 2569 เท่ากับ …......... รีม/คน ลดลงจาก ปี 25….ในช่วงเวลาเดียวกัน เท่ากับ ….......... รีม/คน คิดเป็น …...... %
E48: บรรลุเป้าหมาย | H48: ไม่บรรลุเป้าหมาย
A49: การวิเคราะห์ข้อมูลและสาเหตุ (เป้าหมาย : การใช้กระดาษลดลง ….............% จากปี 2569)
A50: เดือนมกราคม 2569 | D50: บรรลุเป้าหมาย | G50: ไม่บรรลุเป้าหมาย
A51: รายละเอียด :
A52: วิเคราะห์สาเหตุ :
A53: แนวทางจัดการ :
A54: เดือนกุมภาพันธ์ 2569 | D54: บรรลุเป้าหมาย | G54: ไม่บรรลุเป้าหมาย
A55: รายละเอียด :
A56: วิเคราะห์สาเหตุ :
A57: แนวทางจัดการ :
A58: เดือนมีนาคม 2569 | D58: บรรลุเป้าหมาย | G58: ไม่บรรลุเป้าหมาย
A59: รายละเอียด :
A60: วิเคราะห์สาเหตุ :
A61: แนวทางจัดการ :
A62: เดือนเมษายน 2569 | D62: บรรลุเป้าหมาย | G62: ไม่บรรลุเป้าหมาย
A63: รายละเอียด :
A64: วิเคราะห์สาเหตุ :
A65: แนวทางจัดการ :
A66: เดือนพฤษภาคม 2569 | D66: บรรลุเป้าหมาย | G66: ไม่บรรลุเป้าหมาย
A67: รายละเอียด :
A68: วิเคราะห์สาเหตุ :
...

Sheet 2568
K1: แบบฟอร์ม 3.2(1)
A2: บันทึกปริมาณการใช้กระดาษ
A3: เดือน | B3: ปริมาณการใช้กระดาษปี 2567 | F3: ปริมาณการใช้กระดาษปี 2568 | J3: ร้อยละปริมาณการใช้กระดาษ
B4: จำนวนคน | C4: (กิโลกรัม) ปี2567 | D4: ค่ากระดาษ/เดือน (บาท) | E4: (กิโลกรัม/คน) ปี2567 | F4: จำนวนคน | G4: (กิโลกรัม) ปี 2568 | H4: ค่ากระดาษ/เดือน (บาท) | I4: (กิโลกรัม/คน)ปี 2568 | J4: (หน่วย)ปี2568 | K4: (หน่วย/คน)ปี2568
A5: ม.ค. | B5: 94 | C5: 202.5 | D5: 8700 | E5: 2.1315789 | F5: 95 | G5: =[1]แต่ละหน่วยงาน!C108 -> 194.4 | H5: =G5*42.96296296296 -> 8352 | I5: =G5/F5 -> 2.0463158 | J5: =(G5-C5)/C5 -> -0.04 | K5: =(I5-E5)/E5 -> -0.04
A6: ก.พ. | B6: 94 | C6: 226.8 | D6: 9744 | E6: 2.3873684 | F6: 95 | G6: =[1]แต่ละหน่วยงาน!D108 -> 175.5 | H6: =G6*42.96296296296 -> 7540 | I6: =G6/F6 -> 1.8473684 | J6: =(G6-C6)/C6 -> -0.22619048 | K6: =(I6-E6)/E6 -> -0.22619048
A7: มี.ค. | B7: 94 | C7: 224.1 | D7: 9628 | E7: 2.3589474 | F7: 95 | G7: =[1]แต่ละหน่วยงาน!E108 -> 245.7 | H7: =G7*42.96296296296 -> 10556 | I7: =G7/F7 -> 2.5863158 | J7: =(G7-C7)/C7 -> 0.096385542 | K7: =(I7-E7)/E7 -> 0.096385542
A8: เม.ย. | B8: 94 | C8: 91.8 | D8: 3944 | E8: 0.96631579 | F8: 95 | G8: =[1]แต่ละหน่วยงาน!F108 -> 189 | H8: =G8*42.96296296296 -> 8120 | I8: =G8/F8 -> 1.9894737 | J8: =(G8-C8)/C8 -> 1.0588235 | K8: =(I8-E8)/E8 -> 1.0588235
A9: พ.ค. | B9: 94 | C9: 151.2 | D9: 6496 | E9: 1.5915789 | F9: 95 | G9: =[1]แต่ละหน่วยงาน!G108 -> 126.9 | H9: =G9*42.96296296296 -> 5452 | I9: =G9/F9 -> 1.3357895 | J9: =(G9-C9)/C9 -> -0.16071429 | K9: =(I9-E9)/E9 -> -0.16071429
A10: มิ.ย. | B10: 94 | C10: 172.8 | D10: 7424 | E10: 1.8189474 | F10: 95 | G10: =[1]แต่ละหน่วยงาน!H108 -> 183.6 | H10: =G10*42.96296296296 -> 7888 | I10: =G10/F10 -> 1.9326316 | J10: =(G10-C10)/C10 -> 0.0625 | K10: =(I10-E10)/E10 -> 0.0625
A11: ก.ค. | B11: 94 | C11: 132.3 | D11: 5684 | E11: 1.3926316 | F11: 95 | G11: =[1]แต่ละหน่วยงาน!I108 -> 159.3 | H11: =G11*42.96296296296 -> 6844 | I11: =G11/F11 -> 1.6768421 | J11: =(G11-C11)/C11 -> 0.20408163 | K11: =(I11-E11)/E11 -> 0.20408163
A12: ส.ค. | B12: 94 | C12: 167.4 | D12: 7192 | E12: 1.7621053 | F12: 95 | G12: =[1]แต่ละหน่วยงาน!J108 -> 206.55 | H12: =G12*42.96296296296 -> 8874 | I12: =G12/F12 -> 2.1742105 | J12: =(G12-C12)/C12 -> 0.23387097 | K12: =(I12-E12)/E12 -> 0.23387097
A13: ก.ย. | B13: 94 | C13: 153.9 | D13: 6612 | E13: 1.62 | F13: 95 | G13: =[1]แต่ละหน่วยงาน!K108 -> 198.45 | H13: =G13*42.96296296296 -> 8526 | I13: =G13/F13 -> 2.0889474 | J13: =(G13-C13)/C13 -> 0.28947368 | K13: =(I13-E13)/E13 -> 0.28947368
A14: ต.ค. | B14: 94 | C14: 164.7 | D14: 7076 | E14: 1.7336842 | F14: 95 | G14: =[1]แต่ละหน่วยงาน!L108 -> 140.4 | H14: =G14*42.96296296296 -> 6032 | I14: =G14/F14 -> 1.4778947 | J14: =(G14-C14)/C14 -> -0.14754098 | K14: =(I14-E14)/E14 -> -0.14754098
A15: พ.ย. | B15: 94 | C15: 183.6 | D15: 7888 | E15: 1.9326316 | F15: 95 | G15: =[1]แต่ละหน่วยงาน!M108 -> 213.3 | H15: =G15*42.96296296296 -> 9164 | I15: =G15/F15 -> 2.2452632 | J15: =(G15-C15)/C15 -> 0.16176471 | K15: =(I15-E15)/E15 -> 0.16176471
A16: ธ.ค. | B16: 94 | C16: 210.6 | D16: 9048 | E16: 2.2168421 | F16: 95 | G16: =[1]แต่ละหน่วยงาน!N108 -> 164.7 | H16: =G16*42.96296296296 -> 7076 | I16: =G16/F16 -> 1.7336842 | J16: =(G16-C16)/C16 -> -0.21794872 | K16: =(I16-E16)/E16 -> -0.21794872
A17: เฉลี่ย | B17: 95 | C17: 173.475 | D17: 7453 | E17: 1.8260526 | F17: =AVERAGE(F5:F16) -> 95 | G17: =AVERAGE(G5:G16) -> 183.15 | H17: =AVERAGE(H5:H16) -> 7868.6667 | I17: =G17/F17 -> 1.9278947 | J17: =(G17-C17)/C17 -> 0.055771725 | K17: =(I17-E17)/E17 -> 0.055771725
A18: รวม | B18: 1140 | C18: 2081.7 | D18: 89436 | E18: 21.912632 | F18: =SUM(F5:F16) -> 1140 | G18: =SUM(G5:G16) -> 2197.8 | H18: =SUM(H5:H16) -> 94424 | I18: =SUM(I5:I16) -> 23.134737 | J18: =(G18-C18)/C18 -> 0.055771725 | K18: =(I18-E18)/E18 -> 0.055771725
A43: สรุปปริมาณการใช้กระดาษ 1. ปริมาณการใช้กระดาษสะสมตั้งแต่เดือน มกราคม ถึง เดือน มิถุนายน ปี 2567 เท่ากับ 1069 กิโลกรัม เพิ่มขึ้นจาก ปี 2566 ในช่วงเวลาเดียวกัน เท่ากับ 793.8 คิดเป็น 25.74% 2. ปริมาณกระดาษต่อคนสะสมตั้งแต่เดือน มกราคม ถึง เดือน มิถุนายน ปี 2567 เท่ากับ 11.3 กิโลกรัม/คน เพิ่มขึ้นจาก ปี 2566 ในช่วงเวลาเดียวกัน เท่ากับ 8.45 กิโลกรัม/คน คิดเป็น 25.22% 3. ปริมาณการใช้กระดาษเฉลี่ยตั้งแต่เดือน มกราคม ถึง เดือน มิถุนายน ปี 2567 เท่ากับ 178.2 กิโลกรัม เพิ่มขึ้นจาก ปี 2566 ในช่วงเวลาเดียวกัน เท่ากับ 132.3 คิดเป็น 25.74% 4. ปริมาณกระดาษต่อคนเฉลี่ยตั้งแต่เดือน มกราคม ถึง เดือน มิถุนายน ปี 2567 เท่ากับ 1.88 กิโลกรัม/คน เพิ่มขึ้นจาก ปี 2566 ในช่วงเวลาเดียวกัน เท่ากับ 1.41 กิโลกรัม/คน คิดเป็น 25.22%
A48: การวิเคราะห์ข้อมูลและสาเหตุ (เป้าหมาย : การใช้กระดาษลดลง 1% จากปี 2567)
A49: เดือนมกราคม 2568
A50: รายละเอียด : ผลการใช้กระดาษ ประจำเดือน มกราคม 2568 พบว่า ปริมาณการใช้กระดาษ ลดลง เมื่อเทียบกับปี 2567 จำนวน 8.1 กิโลกรัม/คน เมื่อคิดเป็นเปอร์เซ็นต์/คน จะลดลงเท่ากับ -4.0%
A51: วิเคราะห์สาเหตุ : | C51: เนื่องจากบุคคลากรให้ความร่วมมือลดการใช้กระดาษ และใช้กระดาษReuseเพิ่มมากขึ้น
A52: แนวทางจัดการ :
A53: เดือนกุมภาพันธ์ 2568
A54: รายละเอียด : ผลการใช้กระดาษ ประจำเดือน กุมภาพันธ์ 2568 พบว่า ปริมาณการใช้กระดาษ ลดลง เมื่อเทียบกับปี 2567 จำนวน 51.3 กิโลกรัม/คน เมื่อคิดเป็นเปอร์เซ็นต์/คน จะลดลงเท่ากับ -22.6%
A55: วิเคราะห์สาเหตุ : | C55: เนื่องจากบุคคลากรให้ความร่วมมือลดการใช้กระดาษ และใช้กระดาษReuseเพิ่มมากขึ้น
A56: แนวทางจัดการ :
A57: เดือนมีนาคม 2568
A58: รายละเอียด : ผลการใช้กระดาษ ประจำเดือน มีนาคม 2568 พบว่า ปริมาณการใช้กระดาษ เพิ่มขึ้น เมื่อเทียบกับปี 2567 จำนวน 21.6 กิโลกรัม/คน เมื่อคิดเป็นเปอร์เซ็นต์/คน จะเพิ่มขึ้นเท่ากับ 9.6%
A59: วิเคราะห์สาเหตุ : | C59: เนื่องจากมีการจัดทำเอกสารอบรม และเอกสารตรวจประเมินและส่งงานวิจัยภายในหน่วยงาน
A60: แนวทางจัดการ : | C60: กำหนดมาตรการการใช้กระดาษReuseเพิ่มมากขึ้น
A61: เดือนเมษายน 2568
A62: รายละเอียด : ผลการใช้กระดาษ ประจำเดือน เมษายน 2568 พบว่า ปริมาณการใช้กระดาษ เพิ่มขึ้น เมื่อเทียบกับปี 2567 จำนวน 97.2 กิโลกรัม/คน เมื่อคิดเป็นเปอร์เซ็นต์/คน จะเพิ่มขึ้นเท่ากับ 105.9%
A63: วิเคราะห์สาเหตุ : | C63: เนื่องจากมีการจัดทำเอกสารอบรม และเอกสารตรวจประเมินและส่งงานวิจัยภายในหน่วยงาน
A64: แนวทางจัดการ : | C64: กำหนดมาตรการการใช้กระดาษReuseเพิ่มมากขึ้น
A65: เดือนพฤษภาคม 2568
A66: รายละเอียด : ผลการใช้กระดาษ ประจำเดือน พฤษภาคม 2568 พบว่า ปริมาณการใช้กระดาษ ลดลง เมื่อเทียบกับปี 2567 จำนวน 24.28 กิโลกรัม/คน เมื่อคิดเป็นเปอร์เซ็นต์/คน จะลดลงเท่ากับ -16.1%
A67: วิเคราะห์สาเหตุ : | C67: เนื่องจากบุคคลากรให้ความร่วมมือลดการใช้กระดาษ และใช้กระดาษReuseเพิ่มมากขึ้น
A68: แนวทางจัดการ :
...

Sheet 2567
K1: แบบฟอร์ม 3.2(1)
A2: บันทึกปริมาณการใช้กระดาษ
A3: เดือน | B3: ปริมาณการใช้กระดาษปี 2566 | F3: ปริมาณการใช้กระดาษปี 2567 | J3: ร้อยละปริมาณการใช้กระดาษ
B4: จำนวนคน | C4: (กิโลกรัม) ปี2566 | D4: ค่ากระดาษ/เดือน (บาท) | E4: (กิโลกรัม/คน) ปี2566 | F4: จำนวนคน | G4: (กิโลกรัม) ปี 2567 | H4: ค่ากระดาษ/เดือน (บาท) | I4: (กิโลกรัม/คน)ปี 2567 | J4: (หน่วย)ปี2567 | K4: (หน่วย/คน)ปี2567
A5: ม.ค. | B5: 94 | C5: 105.3 | D5: 4524 | E5: =C5/B5 -> 1.1202128 | F5: 95 | G5: 202.5 | H5: 8700 | I5: =G5/F5 -> 2.1315789 | J5: =(G5-C5)/C5 -> 0.92307692 | K5: =(I5-E5)/E5 -> 0.90283401
A6: ก.พ. | B6: 94 | C6: 162 | D6: 6960 | E6: =C6/B6 -> 1.7234043 | F6: 95 | G6: 226.8 | H6: 9744 | I6: =G6/F6 -> 2.3873684 | J6: =(G6-C6)/C6 -> 0.4 | K6: =(I6-E6)/E6 -> 0.38526316
A7: มี.ค. | B7: 94 | C7: 172.8 | D7: 7424 | E7: =C7/B7 -> 1.8382979 | F7: 95 | G7: 224.1 | H7: 9628 | I7: =G7/F7 -> 2.3589474 | J7: =(G7-C7)/C7 -> 0.296875 | K7: =(I7-E7)/E7 -> 0.28322368
A8: เม.ย. | B8: 94 | C8: 116.1 | D8: 4988 | E8: =C8/B8 -> 1.2351064 | F8: 95 | G8: 91.8 | H8: 3944 | I8: =G8/F8 -> 0.96631579 | J8: =(G8-C8)/C8 -> -0.20930233 | K8: =(I8-E8)/E8 -> -0.21762546
A9: พ.ค. | B9: 94 | C9: 132.3 | D9: 5684 | E9: =C9/B9 -> 1.4074468 | F9: 95 | G9: 151.2 | H9: 6496 | I9: =G9/F9 -> 1.5915789 | J9: =(G9-C9)/C9 -> 0.14285714 | K9: =(I9-E9)/E9 -> 0.13082707
A10: มิ.ย. | B10: 94 | C10: 105.3 | D10: 4524 | E10: =C10/B10 -> 1.1202128 | F10: 95 | G10: 172.8 | H10: 7424 | I10: =G10/F10 -> 1.8189474 | J10: =(G10-C10)/C10 -> 0.64102564 | K10: =(I10-E10)/E10 -> 0.62375169
A11: ก.ค. | B11: 94 | C11: 108 | D11: 4640 | E11: =C11/B11 -> 1.1489362 | F11: 95 | G11: =[1]แต่ละหน่วยงาน!I88 -> 132.3 | H11: =G11*42.96296296296 -> 5684 | I11: =G11/F11 -> 1.3926316 | J11: =(G11-C11)/C11 -> 0.225 | K11: =(I11-E11)/E11 -> 0.21210526
A12: ส.ค. | B12: 94 | C12: 170.1 | D12: 7308 | E12: =C12/B12 -> 1.8095745 | F12: 95 | G12: =[1]แต่ละหน่วยงาน!J88 -> 167.4 | H12: =G12*42.96296296296 -> 7192 | I12: =G12/F12 -> 1.7621053 | J12: =(G12-C12)/C12 -> -0.015873016 | K12: =(I12-E12)/E12 -> -0.026232247
A13: ก.ย. | B13: 94 | C13: 140.4 | D13: 6032 | E13: =C13/B13 -> 1.493617 | F13: 95 | G13: =[1]แต่ละหน่วยงาน!K88 -> 153.9 | H13: =G13*42.96296296296 -> 6612 | I13: =G13/F13 -> 1.62 | J13: =(G13-C13)/C13 -> 0.096153846 | K13: =(I13-E13)/E13 -> 0.084615385
A14: ต.ค. | B14: 94 | C14: 189 | D14: 8120 | E14: =C14/B14 -> 2.0106383 | F14: 95 | G14: =[1]แต่ละหน่วยงาน!L88 -> 164.7 | H14: =G14*42.96296296296 -> 7076 | I14: =G14/F14 -> 1.7336842 | J14: =(G14-C14)/C14 -> -0.12857143 | K14: =(I14-E14)/E14 -> -0.13774436
A15: พ.ย. | B15: 94 | C15: 305.1 | D15: 13108 | E15: =C15/B15 -> 3.2457447 | F15: 95 | G15: =[1]แต่ละหน่วยงาน!M88 -> 164.7 | H15: =G15*42.96296296296 -> 7076 | I15: =G15/F15 -> 1.7336842 | J15: =(G15-C15)/C15 -> -0.46017699 | K15: =(I15-E15)/E15 -> -0.46585934
A16: ธ.ค. | B16: 94 | C16: 378 | D16: 16240 | E16: =C16/B16 -> 4.0212766 | F16: 95 | G16: =[1]แต่ละหน่วยงาน!N88 -> 175.5 | H16: =G16*42.96296296296 -> 7540 | I16: =G16/F16 -> 1.8473684 | J16: =(G16-C16)/C16 -> -0.53571429 | K16: =(I16-E16)/E16 -> -0.5406015
A17: เฉลี่ย | B17: =AVERAGE(B5:B16) -> 94 | C17: =AVERAGE(C5:C16) -> 173.7 | D17: =AVERAGE(D5:D16) -> 7462.6667 | E17: =AVERAGE(E5:E16) -> 1.8478723 | F17: =AVERAGE(F5:F16) -> 95 | G17: =AVERAGE(G5:G16) -> 168.975 | H17: =AVERAGE(H5:H16) -> 7259.6667 | I17: =G17/F17 -> 1.7786842 | J17: =(G17-C17)/C17 -> -0.027202073 | K17: =(I17-E17)/E17 -> -0.037442051
A18: รวม | B18: =SUM(B5:B16) -> 1128 | C18: =SUM(C5:C16) -> 2084.4 | D18: =SUM(D5:D16) -> 89552 | E18: =SUM(E5:E16) -> 22.174468 | F18: =SUM(F5:F16) -> 1140 | G18: =SUM(G5:G16) -> 2027.7 | H18: =SUM(H5:H16) -> 87116 | I18: =SUM(I5:I16) -> 21.344211 | J18: =(G18-C18)/C18 -> -0.027202073 | K18: =(I18-E18)/E18 -> -0.037442051
A43: สรุปปริมาณการใช้กระดาษ 1. ปริมาณการใช้กระดาษสะสมตั้งแต่เดือน มกราคม ถึง เดือน มิถุนายน ปี 2567 เท่ากับ 1069 กิโลกรัม เพิ่มขึ้นจาก ปี 2566 ในช่วงเวลาเดียวกัน เท่ากับ 793.8 คิดเป็น 25.74% 2. ปริมาณกระดาษต่อคนสะสมตั้งแต่เดือน มกราคม ถึง เดือน มิถุนายน ปี 2567 เท่ากับ 11.3 กิโลกรัม/คน เพิ่มขึ้นจาก ปี 2566 ในช่วงเวลาเดียวกัน เท่ากับ 8.45 กิโลกรัม/คน คิดเป็น 25.22% 3. ปริมาณการใช้กระดาษเฉลี่ยตั้งแต่เดือน มกราคม ถึง เดือน มิถุนายน ปี 2567 เท่ากับ 178.2 กิโลกรัม เพิ่มขึ้นจาก ปี 2566 ในช่วงเวลาเดียวกัน เท่ากับ 132.3 คิดเป็น 25.74% 4. ปริมาณกระดาษต่อคนเฉลี่ยตั้งแต่เดือน มกราคม ถึง เดือน มิถุนายน ปี 2567 เท่ากับ 1.88 กิโลกรัม/คน เพิ่มขึ้นจาก ปี 2566 ในช่วงเวลาเดียวกัน เท่ากับ 1.41 กิโลกรัม/คน คิดเป็น 25.22%
A48: การวิเคราะห์ข้อมูลและสาเหตุ (เป้าหมาย : การใช้กระดาษลดลง 1% จากปี 2566)
A49: เดือนมกราคม 2567
A50: รายละเอียด : | B50: ผลการใช้กระดาษ ประจำเดือน มกราคม 2567 พบว่า ปริมาณการใช้กระดาษ เพิ่มขึ้น เมื่อเทียบกับปี 2566 จำนวน 97.2 กิโลกรัม/คน เมื่อคิดเป็นเปอร์เซ็นต์/คน จะเพิ่มขึ้นเท่ากับ 92.3%
A51: วิเคราะห์สาเหตุ : | C51: เนื่องจากมีการจัดทำเอกสารตรวจประเมินและส่งงานวิจัยภายในหน่วยงาน
A52: แนวทางจัดการ : | C52: กำหนดมาตรการการใช้กระดาษReuseเพิ่มมากขึ้น
A53: เดือนกุมภาพันธ์ 2567
A54: รายละเอียด : ผลการใช้กระดาษ ประจำเดือน กุมภาพันธ์ 2567 พบว่า ปริมาณการใช้กระดาษ เพิ่มขึ้น เมื่อเทียบกับปี 2566 จำนวน 64.8 กิโลกรัม/คน เมื่อคิดเป็นเปอร์เซ็นต์/คน จะเพิ่มขึ้นเท่ากับ 40.0%
A55: วิเคราะห์สาเหตุ : | C55: เนื่องจากมีการจัดทำเอกสารตรวจประเมินและส่งงานวิจัยภายในหน่วยงาน
A56: แนวทางจัดการ : | C56: กำหนดมาตรการการใช้กระดาษReuseเพิ่มมากขึ้น
A57: เดือนมีนาคม 2567
A58: รายละเอียด : ผลการใช้กระดาษ ประจำเดือน มีนาคม 2567 พบว่า ปริมาณการใช้กระดาษ เพิ่มขึ้น เมื่อเทียบกับปี 2566 จำนวน 51.3 กิโลกรัม/คน เมื่อคิดเป็นเปอร์เซ็นต์/คน จะเพิ่มขึ้นเท่ากับ 29.7%
A59: วิเคราะห์สาเหตุ : | C59: เนื่องจากมีการจัดทำเอกสารอบรม และเอกสารตรวจประเมินและส่งงานวิจัยภายในหน่วยงาน
A60: แนวทางจัดการ : | C60: กำหนดมาตรการการใช้กระดาษReuseเพิ่มมากขึ้น
A61: เดือนเมษายน 2567
A62: รายละเอียด : ผลการใช้กระดาษ ประจำเดือน เมษายน 2567 พบว่า ปริมาณการใช้กระดาษ ลดลง เมื่อเทียบกับปี 2566 จำนวน 24.3 กิโลกรัม/คน เมื่อคิดเป็นเปอร์เซ็นต์/คน จะลดลงเท่ากับ -20.9%
A63: วิเคราะห์สาเหตุ : | C63: เนื่องจากบุคคลากรให้ความร่วมมือลดการใช้กระดาษ และใช้กระดาษReuseเพิ่มมากขึ้น
A64: แนวทางจัดการ :
A65: เดือนพฤษภาคม 2567
A66: รายละเอียด : ผลการใช้กระดาษ ประจำเดือน พฤษภาคม 2567 พบว่า ปริมาณการใช้กระดาษ เพิ่มขึ้น เมื่อเทียบกับปี 2566 จำนวน 18.9 กิโลกรัม/คน เมื่อคิดเป็นเปอร์เซ็นต์/คน จะเพิ่มขึ้นเท่ากับ 14.3%
A67: วิเคราะห์สาเหตุ : | C67: เนื่องจากมีการจัดทำเอกสารอบรม และเอกสารตรวจประเมินและส่งงานวิจัยภายในหน่วยงาน
A68: แนวทางจัดการ : | C68: กำหนดมาตรการการใช้กระดาษReuseเพิ่มมากขึ้น
...

Sheet แต่ละหน่วยงาน
A2: ปี | B2: iqs | C2: มกราคม | D2: กุมภาพันธ์ | E2: มีนาคม | F2: เมษายน | G2: พฤษภาคม | H2: มิถุนายน | I2: กรกฎาคม | J2: สิงหาคม | K2: กันยายน | L2: ตุลาคม | M2: พฤศจิกายน | N2: ธันวาคม | O2: รวม
A3: 65 | B3: สำนักงาน | C3: 7 | D3: 2 | E3: 2 | F3: 5 | G3: 2 | H3: 2 | I3: 2 | J3: 1 | K3: 2 | L3: 1 | M3: 1 | N3: 1 | O3: 28
B4: ห้องปฏิบัติการ | C4: 1 | F4: 1 | G4: 1 | K4: 1 | M4: 15 | N4: 1 | O4: 20
B5: โครงการ | E5: 1 | J5: 2 | L5: 1 | N5: 1 | O5: 5
B6: จุลินทรีย์ | C6: 3 | D6: 7 | E6: 15 | F6: 3 | G6: 3 | H6: 2 | I6: 3 | J6: 2 | K6: 2 | L6: 1 | O6: 41
B7: รวมริม | C7: 11 | D7: 9 | E7: 18 | F7: 9 | G7: 6 | H7: 4 | I7: 5 | J7: 5 | K7: 5 | L7: 3 | M7: 16 | N7: 3 | O7: 94
B8: รวมกิโลกรัม | C8: 29.7 | D8: 24.3 | E8: 48.6 | F8: 24.3 | G8: 16.2 | H8: 10.8 | I8: 13.5 | J8: 13.5 | K8: 13.5 | L8: 8.1 | M8: 43.2 | N8: 8.1 | O8: 253.8
A10: ปี | B10: สำนักวิจัย | C10: มกราคม | D10: กุมภาพันธ์ | E10: มีนาคม | F10: เมษายน | G10: พฤษภาคม | H10: มิถุนายน | I10: กรกฎาคม | J10: สิงหาคม | K10: กันยายน | L10: ตุลาคม | M10: พฤศจิกายน | N10: ธันวาคม | O10: รวม
A11: 65 | B11: สำนักงาน | L11: 21 | M11: 35 | N11: 0 | O11: 56
B12: รวมริม | C12: 0 | D12: 0 | E12: 0 | F12: 0 | G12: 0 | H12: 0 | I12: 0 | J12: 0 | K12: 0 | L12: 21 | M12: 35 | N12: 0 | O12: 56
B13: รวมกิโลกรัม | C13: 0 | D13: 0 | E13: 0 | F13: 0 | G13: 0 | H13: 0 | I13: 0 | J13: 0 | K13: 0 | L13: 56.7 | M13: 94.5 | N13: 0 | O13: 151.2
A15: ปี | B15: โครงการข้าว | C15: มกราคม | D15: กุมภาพันธ์ | E15: มีนาคม | F15: เมษายน | G15: พฤษภาคม | H15: มิถุนายน | I15: กรกฎาคม | J15: สิงหาคม | K15: กันยายน | L15: ตุลาคม | M15: พฤศจิกายน | N15: ธันวาคม | O15: รวม
A16: 65 | B16: สำนักงาน | C16: 10 | D16: 5 | E16: 20 | F16: 10 | G16: 5 | H16: 5 | I16: 5 | J16: 5 | K16: 15 | L16: 10 | M16: 5 | N16: 5 | O16: 100
B17: รวมริม | C17: 10 | D17: 5 | E17: 20 | F17: 10 | G17: 5 | H17: 5 | I17: 5 | J17: 5 | K17: 15 | L17: 10 | M17: 5 | N17: 5 | O17: 100
B18: รวมกิโลกรัม | C18: 27 | D18: 13.5 | E18: 54 | F18: 27 | G18: 13.5 | H18: 13.5 | I18: 13.5 | J18: 13.5 | K18: 40.5 | L18: 27 | M18: 13.5 | N18: 13.5 | O18: 270
A20: ปี | B20: ICAP | C20: มกราคม | D20: กุมภาพันธ์ | E20: มีนาคม | F20: เมษายน | G20: พฤษภาคม | H20: มิถุนายน | I20: กรกฎาคม | J20: สิงหาคม | K20: กันยายน | L20: ตุลาคม | M20: พฤศจิกายน | N20: ธันวาคม | O20: รวม
A21: 65 | B21: สำนักงาน | C21: 10 | D21: 15 | E21: 15 | F21: 5 | G21: 10 | H21: 15 | I21: 15 | J21: 15 | K21: 10 | L21: 15 | M21: 10 | N21: 10 | O21: 145
B22: รวมริม | C22: 10 | D22: 15 | E22: 15 | F22: 5 | G22: 10 | H22: 15 | I22: 15 | J22: 15 | K22: 10 | L22: 15 | M22: 10 | N22: 10 | O22: 145
B23: รวมกิโลกรัม | C23: 27 | D23: 40.5 | E23: 40.5 | F23: 13.5 | G23: 27 | H23: 40.5 | I23: 40.5 | J23: 40.5 | K23: 27 | L23: 40.5 | M23: 27 | N23: 27 | O23: 391.5
A25: ปี | B25: สมุนไพร | C25: มกราคม | D25: กุมภาพันธ์ | E25: มีนาคม | F25: เมษายน | G25: พฤษภาคม | H25: มิถุนายน | I25: กรกฎาคม | J25: สิงหาคม | K25: กันยายน | L25: ตุลาคม | M25: พฤศจิกายน | N25: ธันวาคม | O25: รวม
A26: 65 | B26: สำนักงาน | C26: 1 | D26: 0 | E26: 1 | F26: 0 | G26: 1 | H26: 0 | I26: 1 | J26: 0 | K26: 1 | L26: 0 | M26: 1 | N26: 0 | O26: 6
B27: รวมริม | C27: 1 | D27: 0 | E27: 1 | F27: 0 | G27: 1 | H27: 0 | I27: 1 | J27: 0 | K27: 1 | L27: 0 | M27: 1 | N27: 0 | O27: 6
B28: รวมกิโลกรัม | C28: 2.7 | D28: 0 | E28: 2.7 | F28: 0 | G28: 2.7 | H28: 0 | I28: 2.7 | J28: 0 | K28: 2.7 | L28: 0 | M28: 2.7 | N28: 0 | O28: 16.2
A30: ปี | B30: ฝ่าย | C30: มกราคม | D30: กุมภาพันธ์ | E30: มีนาคม | F30: เมษายน | G30: พฤษภาคม | H30: มิถุนายน | I30: กรกฎาคม | J30: สิงหาคม | K30: กันยายน | L30: ตุลาคม | M30: พฤศจิกายน | N30: ธันวาคม | O30: รวม
A31: 66 | B31: สำนักงาน | C31: 2 | D31: 2 | E31: 1 | F31: 1 | I31: 4 | J31: 2 | K31: 1 | L31: 1 | M31: 5 | N31: 6 | O31: 25
B32: ห้องปฏิบัติการ | C32: 1 | D32: 3 | E32: 2 | G32: 1 | H32: 2 | J32: 1 | L32: 1 | N32: 2 | O32: 13
B33: โครงการ | C33: 1 | D33: 20 | E33: 20 | F33: 1 | G33: 2 | M33: 5 | N33: 10 | O33: 59
B34: จุลินทรีย์ | C34: 1 | F34: 1 | H34: 2 | M34: 1 | N34: 1 | O34: 6
B35: รวมริม | C35: 5 | D35: 25 | E35: 23 | F35: 3 | G35: 3 | H35: 4 | I35: 4 | J35: 3 | K35: 1 | L35: 2 | M35: 11 | N35: 19 | O35: 103
B36: รวมกิโลกรัม | C36: 13.5 | D36: 67.5 | E36: 62.1 | F36: 8.1 | G36: 8.1 | H36: 10.8 | I36: 10.8 | J36: 8.1 | K36: 2.7 | L36: 5.4 | M36: 29.7 | N36: 51.3 | O36: 278.1
A38: ปี | B38: ฝ่าย | C38: มกราคม | D38: กุมภาพันธ์ | E38: มีนาคม | F38: เมษายน | G38: พฤษภาคม | H38: มิถุนายน | I38: กรกฎาคม | J38: สิงหาคม | K38: กันยายน | L38: ตุลาคม | M38: พฤศจิกายน | N38: ธันวาคม | O38: รวม
A39: 66 | B39: สำนักงาน | C39: 13 | D39: 15 | E39: 10 | F39: 25 | G39: 30 | H39: 20 | I39: 15 | J39: 25 | K39: 15 | L39: 43 | M39: 76 | N39: 101 | O39: 388
B40: รวมริม | C40: 13 | D40: 15 | E40: 10 | F40: 25 | G40: 30 | H40: 20 | I40: 15 | J40: 25 | K40: 15 | L40: 43 | M40: 76 | N40: 101 | O40: 388
B41: รวมกิโลกรัม | C41: 35.1 | D41: 40.5 | E41: 27 | F41: 67.5 | G41: 81 | H41: 54 | I41: 40.5 | J41: 67.5 | K41: 40.5 | L41: 116.1 | M41: 205.2 | N41: 272.7 | O41: 1047.6
A43: ปี | B43: โครงการข้าว | C43: มกราคม | D43: กุมภาพันธ์ | E43: มีนาคม | F43: เมษายน | G43: พฤษภาคม | H43: มิถุนายน | I43: กรกฎาคม | J43: สิงหาคม | K43: กันยายน | L43: ตุลาคม | M43: พฤศจิกายน | N43: ธันวาคม | O43: รวม
A44: 66 | B44: สำนักงาน | C44: 10 | D44: 5 | E44: 15 | F44: 5 | G44: 5 | H44: 5 | I44: 5 | J44: 10 | K44: 10 | L44: 15 | M44: 10 | N44: 10 | O44: 105
B45: รวมริม | C45: 10 | D45: 5 | E45: 15 | F45: 5 | G45: 5 | H45: 5 | I45: 5 | J45: 10 | K45: 10 | L45: 15 | M45: 10 | N45: 10 | O45: 105
B46: รวมกิโลกรัม | C46: 27 | D46: 13.5 | E46: 40.5 | F46: 13.5 | G46: 13.5 | H46: 13.5 | I46: 13.5 | J46: 27 | K46: 27 | L46: 40.5 | M46: 27 | N46: 27 | O46: 283.5
A48: ปี | B48: ICAP | C48: มกราคม | D48: กุมภาพันธ์ | E48: มีนาคม | F48: เมษายน | G48: พฤษภาคม | H48: มิถุนายน | I48: กรกฎาคม | J48: สิงหาคม | K48: กันยายน | L48: ตุลาคม | M48: พฤศจิกายน | N48: ธันวาคม | O48: รวม
A49: 66 | B49: สำนักงาน | C49: 10 | D49: 15 | E49: 15 | F49: 10 | G49: 10 | H49: 10 | I49: 15 | J49: 25 | K49: 25 | L49: 10 | M49: 15 | N49: 10 | O49: 170
...

Sheet Reuse
K1: แบบฟอร์ม 3.2(1)
A2: บันทึกปริมาณการใช้กระดาษ Reuse
A3: เดือน | B3: ปริมาณการใช้กระดาษปี 2567 | F3: ปริมาณการใช้กระดาษปี 2568 | J3: ร้อยละปริมาณการใช้กระดาษ
B4: จำนวนคน | C4: (กิโลกรัม) ปี2566 | D4: ค่ากระดาษ/เดือน (บาท) | E4: (กิโลกรัม/คน) ปี2566 | F4: จำนวนคน | G4: (กิโลกรัม) ปี 2567 | H4: ค่ากระดาษ/เดือน (บาท) | I4: (กิโลกรัม/คน)ปี 2567 | J4: (หน่วย)ปี2567 | K4: (หน่วย/คน)ปี2567
A5: ม.ค. | B5: 94 | C5: 25 | E5: =C5/B5 -> 0.26595745 | F5: 95 | G5: 30 | I5: =G5/F5 -> 0.31578947 | J5: =(G5-C5)/C5 -> 0.2 | K5: =(I5-E5)/E5 -> 0.18736842
A6: ก.พ. | B6: 94 | C6: 25 | E6: =C6/B6 -> 0.26595745 | F6: 95 | G6: 35 | I6: =G6/F6 -> 0.36842105 | J6: =(G6-C6)/C6 -> 0.4 | K6: =(I6-E6)/E6 -> 0.38526316
A7: มี.ค. | B7: 94 | C7: 23 | E7: =C7/B7 -> 0.24468085 | F7: 95 | G7: 25 | I7: =G7/F7 -> 0.26315789 | J7: =(G7-C7)/C7 -> 0.086956522 | K7: =(I7-E7)/E7 -> 0.075514874
A8: เม.ย. | B8: 94 | C8: 26 | E8: =C8/B8 -> 0.27659574 | F8: 95 | G8: 30 | I8: =G8/F8 -> 0.31578947 | J8: =(G8-C8)/C8 -> 0.15384615 | K8: =(I8-E8)/E8 -> 0.1417004
A9: พ.ค. | B9: 94 | C9: 30 | E9: =C9/B9 -> 0.31914894 | F9: 95 | G9: 35 | I9: =G9/F9 -> 0.36842105 | J9: =(G9-C9)/C9 -> 0.16666667 | K9: =(I9-E9)/E9 -> 0.15438596
A10: มิ.ย. | B10: 94 | C10: 20 | E10: =C10/B10 -> 0.21276596 | F10: 95 | G10: 28 | I10: =G10/F10 -> 0.29473684 | J10: =(G10-C10)/C10 -> 0.4 | K10: =(I10-E10)/E10 -> 0.38526316
A11: ก.ค. | B11: 94 | C11: 18 | E11: =C11/B11 -> 0.19148936 | F11: 95 | G11: 32 | I11: =G11/F11 -> 0.33684211 | J11: =(G11-C11)/C11 -> 0.77777778 | K11: =(I11-E11)/E11 -> 0.75906433
A12: ส.ค. | B12: 94 | C12: 32 | E12: =C12/B12 -> 0.34042553 | F12: 95 | G12: 25 | I12: =G12/F12 -> 0.26315789 | J12: =(G12-C12)/C12 -> -0.21875 | K12: =(I12-E12)/E12 -> -0.22697368
A13: ก.ย. | B13: 94 | C13: 30 | E13: =C13/B13 -> 0.31914894 | F13: 95 | G13: 28 | I13: =G13/F13 -> 0.29473684 | J13: =(G13-C13)/C13 -> -0.066666667 | K13: =(I13-E13)/E13 -> -0.076491228
A14: ต.ค. | B14: 94 | C14: 25 | E14: =C14/B14 -> 0.26595745 | F14: 95 | G14: 30 | I14: =G14/F14 -> 0.31578947 | J14: =(G14-C14)/C14 -> 0.2 | K14: =(I14-E14)/E14 -> 0.18736842
A15: พ.ย. | B15: 94 | C15: 20 | E15: =C15/B15 -> 0.21276596 | F15: 95 | G15: 32 | I15: =G15/F15 -> 0.33684211 | J15: =(G15-C15)/C15 -> 0.6 | K15: =(I15-E15)/E15 -> 0.58315789
A16: ธ.ค. | B16: 94 | C16: 30 | E16: =C16/B16 -> 0.31914894 | F16: 95 | G16: 25 | I16: =G16/F16 -> 0.26315789 | J16: =(G16-C16)/C16 -> -0.16666667 | K16: =(I16-E16)/E16 -> -0.1754386
A17: เฉลี่ย | B17: =AVERAGE(B5:B16) -> 94 | C17: =AVERAGE(C5:C16) -> 25.333333 | E17: =AVERAGE(E5:E16) -> 0.26950355 | F17: =AVERAGE(F5:F16) -> 95 | G17: =AVERAGE(G5:G16) -> 29.583333 | I17: =G17/F17 -> 0.31140351 | J17: =(G17-C17)/C17 -> 0.16776316 | K17: =(I17-E17)/E17 -> 0.15547091
A18: รวม | B18: =SUM(B5:B16) -> 1128 | C18: =SUM(C5:C16) -> 304 | D18: =SUM(D5:D16) -> 0 | E18: =SUM(E5:E16) -> 3.2340426 | F18: =SUM(F5:F16) -> 1140 | G18: =SUM(G5:G16) -> 355 | H18: =SUM(H5:H16) -> 0 | I18: =SUM(I5:I16) -> 3.7368421 | J18: =(G18-C18)/C18 -> 0.16776316 | K18: =(I18-E18)/E18 -> 0.15547091
