Workbook

Sheet ฟอร์มใหม่
K1: แบบฟอร์ม 3.1(1)
A2: บันทึกปริมาณการใช้น้ำ
A3: เดือน | B3: ปริมาณการใช้น้ำปี 25…...... | F3: ปริมาณการใช้น้ำปี 2569 | J3: ร้อยละปริมาณการใช้น้ำ
B4: จำนวนคน | C4: (ลบ.ม.)ปี..... | D4: ค่าน้ำ/เดือน (บาท) | E4: (ลบ.ม./คน) ปี…........ | F4: จำนวนคน | G4: (ลบ.ม) ปี 2569 | H4: ค่าน้ำ/เดือน (บาท) | I4: (ลบ.ม./คน) ปี 2569 | J4: (ลบ.ม.)ปี............. | K4: (ลบ.ม./คน)ปี.............
A5: ม.ค. | C5: 500 | E5: =C5/B5 -> #DIV/0! | I5: =G5/F5 -> #DIV/0! | J5: =(G5-C5)/C5 -> -1 | K5: =(I5-E5)/E5 -> #DIV/0!
A6: ก.พ. | E6: =C6/B6 -> #DIV/0! | I6: =G6/F6 -> #DIV/0! | J6: =(G6-C6)/C6 -> #DIV/0! | K6: =(I6-E6)/E6 -> #DIV/0!
A7: มี.ค. | E7: =C7/B7 -> #DIV/0! | I7: =G7/F7 -> #DIV/0! | J7: =(G7-C7)/C7 -> #DIV/0! | K7: =(I7-E7)/E7 -> #DIV/0!
A8: เม.ย. | E8: =C8/B8 -> #DIV/0! | I8: =G8/F8 -> #DIV/0! | J8: =(G8-C8)/C8 -> #DIV/0! | K8: =(I8-E8)/E8 -> #DIV/0!
A9: พ.ค. | E9: =C9/B9 -> #DIV/0! | I9: =G9/F9 -> #DIV/0! | J9: =(G9-C9)/C9 -> #DIV/0! | K9: =(I9-E9)/E9 -> #DIV/0!
A10: มิ.ย. | E10: =C10/B10 -> #DIV/0! | I10: =G10/F10 -> #DIV/0! | J10: =(G10-C10)/C10 -> #DIV/0! | K10: =(I10-E10)/E10 -> #DIV/0!
A11: ก.ค. | E11: =C11/B11 -> #DIV/0! | I11: =G11/F11 -> #DIV/0! | J11: =(G11-C11)/C11 -> #DIV/0! | K11: =(I11-E11)/E11 -> #DIV/0!
A12: ส.ค. | E12: =C12/B12 -> #DIV/0! | I12: =G12/F12 -> #DIV/0! | J12: =(G12-C12)/C12 -> #DIV/0! | K12: =(I12-E12)/E12 -> #DIV/0!
A13: ก.ย. | E13: =C13/B13 -> #DIV/0! | I13: =G13/F13 -> #DIV/0! | J13: =(G13-C13)/C13 -> #DIV/0! | K13: =(I13-E13)/E13 -> #DIV/0!
A14: ต.ค. | E14: =C14/B14 -> #DIV/0! | I14: =G14/F14 -> #DIV/0! | J14: =(G14-C14)/C14 -> #DIV/0! | K14: =(I14-E14)/E14 -> #DIV/0!
A15: พ.ย. | E15: =C15/B15 -> #DIV/0! | I15: =G15/F15 -> #DIV/0! | J15: =(G15-C15)/C15 -> #DIV/0! | K15: =(I15-E15)/E15 -> #DIV/0!
A16: ธ.ค. | E16: =C16/B16 -> #DIV/0! | I16: =G16/F16 -> #DIV/0! | J16: =(G16-C16)/C16 -> #DIV/0! | K16: =(I16-E16)/E16 -> #DIV/0!
A17: เฉลี่ย | B17: =AVERAGE(B5:B16) -> #DIV/0! | C17: =AVERAGE(C5:C16) -> 500 | D17: =AVERAGE(D5:D16) -> #DIV/0! | E17: =AVERAGE(E5:E16) -> #DIV/0! | F17: =AVERAGE(F5:F16) -> #DIV/0! | G17: =AVERAGE(G5:G16) -> #DIV/0! | H17: =AVERAGE(H5:H16) -> #DIV/0! | I17: =G17/F17 -> #DIV/0! | J17: =(G17-C17)/C17 -> #DIV/0! | K17: =(I17-E17)/E17 -> #DIV/0!
A18: รวม | B18: =SUM(B5:B16) -> 0 | C18: =SUM(C5:C16) -> 500 | D18: =SUM(D5:D16) -> 0 | E18: =SUM(E5:E16) -> #DIV/0! | F18: =SUM(F5:F16) -> 0 | G18: =SUM(G5:G16) -> 0 | H18: =SUM(H5:H16) -> 0 | I18: =SUM(I5:I16) -> #DIV/0! | J18: =(G18-C18)/C18 -> -1 | K18: =(I18-E18)/E18 -> #DIV/0!
A43: สรุปปริมาณการใช้น้ำ 1. การปริมาณน้ำสะสมตั้งแต่เดือน มกราคม ถึง ….............ปี 2569 เท่ากับ …......... ลบ.ม. ลดลงจาก ปี 25….ในช่วงเวลาเดียวกัน เท่ากับ …............. ลบ.ม. คิดเป็น …...... % 2. การปริมาณน้ำต่อคนสะสมตั้งแต่เดือน มกราคม ถึง ….............ปี 2569 เท่ากับ …......... ลบ.ม./คน ลดลงจาก ปี 25….ในช่วงเวลาเดียวกัน เท่ากับ …......... ลบ.ม./คน คิดเป็น …...... % 3. การปริมาณน้ำเฉลี่ยตั้งแต่เดือน มกราคม ถึง ….............ปี 2569 เท่ากับ …......... ลบ.ม. ลดลงจาก ปี 25….ในช่วงเวลาเดียวกัน เท่ากับ …............. ลบ.ม. คิดเป็น …...... % 4. การปริมาณน้ำต่อคนเฉลี่ยตั้งแต่เดือน มกราคม ถึง ….............ปี 2569 เท่ากับ …......... ลบ.ม./คน ลดลงจาก ปี 25….ในช่วงเวลาเดียวกัน เท่ากับ ….......... ลบ.ม./คน คิดเป็น …...... %
E48: บรรลุเป้าหมาย | H48: ไม่บรรลุเป้าหมาย
A49: การวิเคราะห์ข้อมูลและสาเหตุ (เป้าหมาย 2569 : การใช้น้ำลดลง …...........% จากปี 25…....)
A50: เดือนมกราคม 2569 | D50: บรรลุเป้าหมาย | G50: ไม่บรรลุเป้าหมาย
A51: รายละเอียด :
A52: วิเคราะห์สาเหตุ :
A53: แนวทางจัดการ :
A54: เดือนกุมภาพันธ์ 2569 | D54: บรรลุเป้าหมาย | G54: ไม่บรรลุเป้าหมาย
A55: รายละเอียด :
A56: วิเคราะห์สาเหตุ :
A57: แนวทางจัดการ :
A58: เดือนมีนาคม 2569 | D58: บรรลุเป้าหมาย | G58: ไม่บรรลุเป้าหมาย
A59: รายละเอียด :
A60: วิเคราะห์สาเหตุ :
A61: แนวทางจัดการ :
A62: เดือนเมษายน 2569 | D62: บรรลุเป้าหมาย | G62: ไม่บรรลุเป้าหมาย
A63: รายละเอียด :
A64: วิเคราะห์สาเหตุ :
A65: แนวทางจัดการ :
A66: เดือนพฤษภาคม 2569 | D66: บรรลุเป้าหมาย | G66: ไม่บรรลุเป้าหมาย
A67: รายละเอียด :
A68: วิเคราะห์สาเหตุ :
...

Sheet 2567
K1: แบบฟอร์ม 3.2(1)
A2: บันทึกปริมาณการใช้น้ำ
A3: เดือน | B3: ปริมาณการใช้น้ำปี 2566 | F3: ปริมาณการใช้น้ำปี 2567 | J3: ร้อยละปริมาณการใช้น้ำ | M3: ป้อนข้อมูลตรงนี้
B4: จำนวนคน | C4: (หน่วย) ปี2566 | D4: ค่าน้ำ/เดือน (บาท) | E4: (หน่วย/คน) ปี2566 | F4: จำนวนคน | G4: (หน่วย) ปี 2567 | H4: ค่าน้ำ/เดือน (บาท) | I4: (หน่วย/คน)ปี 2567 | J4: (หน่วย)ปี2567 | K4: (หน่วย/คน)ปี2567 | N4: ข้อมูล1(หลัง) | O4: ข้อมูล2(ก่อน)
A5: ม.ค. | B5: 94 | C5: 422 | D5: 3376 | E5: =C5/B5 -> 4.4893617 | F5: 95 | G5: =P5 -> 291 | H5: =G5*8 -> 2328 | I5: =G5/F5 -> 3.0631579 | J5: =(G5-C5)/C5 -> -0.31042654 | K5: =(I5-E5)/E5 -> -0.31768521 | M5: มกราคม | N5: 272074.9 | O5: 271783.9 | P5: =N5-O5 -> 291
A6: ก.พ. | B6: 94 | C6: 396 | D6: 3168 | E6: =C6/B6 -> 4.212766 | F6: 95 | G6: =P6 -> 467.3 | H6: =G6*8 -> 3738.4 | I6: =G6/F6 -> 4.9189474 | J6: =(G6-C6)/C6 -> 0.18005051 | K6: =(I6-E6)/E6 -> 0.16762892 | M6: กุมภาพันธ์ | N6: 272542.2 | O6: 272074.9 | P6: =N6-O6 -> 467.3
A7: มี.ค. | B7: 94 | C7: 776 | D7: 6208 | E7: =C7/B7 -> 8.2553191 | F7: 95 | G7: =P7 -> 507.6 | H7: =G7*8 -> 4060.8 | I7: =G7/F7 -> 5.3431579 | J7: =(G7-C7)/C7 -> -0.34587629 | K7: =(I7-E7)/E7 -> -0.3527618 | M7: มีนาคม | N7: 273049.8 | O7: 272542.2 | P7: =N7-O7 -> 507.6
A8: เม.ย. | B8: 94 | C8: 548 | D8: 4384 | E8: =C8/B8 -> 5.8297872 | F8: 95 | G8: =P8 -> 452.3 | H8: =G8*8 -> 3618.4 | I8: =G8/F8 -> 4.7610526 | J8: =(G8-C8)/C8 -> -0.17463504 | K8: =(I8-E8)/E8 -> -0.18332309 | M8: เมษายน | N8: 273502.1 | O8: 273049.8 | P8: =N8-O8 -> 452.3
A9: พ.ค. | B9: 94 | C9: 411 | D9: 3288 | E9: =C9/B9 -> 4.3723404 | F9: 95 | G9: =P9 -> 408.7 | H9: =G9*8 -> 3269.6 | I9: =G9/F9 -> 4.3021053 | J9: =(G9-C9)/C9 -> -0.0055961071 | K9: =(I9-E9)/E9 -> -0.016063516 | M9: พฤษภาคม | N9: 273910.8 | O9: 273502.1 | P9: =N9-O9 -> 408.7
A10: มิ.ย. | B10: 94 | C10: 334 | D10: 2672 | E10: =C10/B10 -> 3.5531915 | F10: 95 | G10: =P10 -> 369 | H10: =G10*8 -> 2952 | I10: =G10/F10 -> 3.8842105 | J10: =(G10-C10)/C10 -> 0.10479042 | K10: =(I10-E10)/E10 -> 0.093161046 | M10: มิถุนายน | N10: 274279.8 | O10: 273910.8 | P10: =N10-O10 -> 369
A11: ก.ค. | B11: 94 | C11: 519 | D11: 4152 | E11: =C11/B11 -> 5.5212766 | F11: 95 | G11: =P11 -> 462.1 | H11: =G11*8 -> 3696.8 | I11: =G11/F11 -> 4.8642105 | J11: =(G11-C11)/C11 -> -0.10963391 | K11: =(I11-E11)/E11 -> -0.11900619 | M11: กรกฎาคม | N11: 274741.9 | O11: 274279.8 | P11: =N11-O11 -> 462.1
A12: ส.ค. | B12: 94 | C12: 505 | D12: 4040 | E12: =C12/B12 -> 5.3723404 | F12: 95 | G12: =P12 -> 348.6 | H12: =G12*8 -> 2788.8 | I12: =G12/F12 -> 3.6694737 | J12: =(G12-C12)/C12 -> -0.30970297 | K12: =(I12-E12)/E12 -> -0.31696925 | M12: สิงหาคม | N12: 275090.5 | O12: 274741.9 | P12: =N12-O12 -> 348.6
A13: ก.ย. | B13: 94 | C13: 379 | D13: 3032 | E13: =C13/B13 -> 4.0319149 | F13: 95 | G13: =P13 -> 355.5 | H13: =G13*8 -> 2844 | I13: =G13/F13 -> 3.7421053 | J13: =(G13-C13)/C13 -> -0.062005277 | K13: =(I13-E13)/E13 -> -0.071878906 | M13: กันยายน | N13: 275446 | O13: 275090.5 | P13: =N13-O13 -> 355.5
A14: ต.ค. | B14: 94 | C14: 412 | D14: 3296 | E14: =C14/B14 -> 4.3829787 | F14: 95 | G14: =P14 -> 463.6 | H14: =G14*8 -> 3708.8 | I14: =G14/F14 -> 4.88 | J14: =(G14-C14)/C14 -> 0.12524272 | K14: =(I14-E14)/E14 -> 0.11339806 | M14: ตุลาคม | N14: 275909.6 | O14: 275446 | P14: =N14-O14 -> 463.6
A15: พ.ย. | B15: 94 | C15: 472 | D15: 3776 | E15: =C15/B15 -> 5.0212766 | F15: 95 | G15: =P15 -> 508.1 | H15: =G15*8 -> 4064.8 | I15: =G15/F15 -> 5.3484211 | J15: =(G15-C15)/C15 -> 0.076483051 | K15: =(I15-E15)/E15 -> 0.06515165 | M15: พฤศจิกายน | N15: 276417.7 | O15: 275909.6 | P15: =N15-O15 -> 508.1
A16: ธ.ค. | B16: 94 | C16: 349 | D16: 2792 | E16: =C16/B16 -> 3.712766 | F16: 95 | G16: =P16 -> 1032.6 | H16: =G16*8 -> 8260.8 | I16: =G16/F16 -> 10.869474 | J16: =(G16-C16)/C16 -> 1.9587393 | K16: =(I16-E16)/E16 -> 1.9275946 | M16: ธันวาคม | N16: 277450.3 | O16: 276417.7 | P16: =N16-O16 -> 1032.6
A17: เฉลี่ย | B17: =AVERAGE(B5:B16) -> 94 | C17: =AVERAGE(C5:C16) -> 460.25 | D17: =AVERAGE(D5:D16) -> 3682 | E17: =AVERAGE(E5:E16) -> 4.8962766 | F17: =AVERAGE(F5:F16) -> 95 | G17: =AVERAGE(G5:G16) -> 472.2 | H17: =AVERAGE(H5:H16) -> 3777.6 | I17: =G17/F17 -> 4.9705263 | J17: =(G17-C17)/C17 -> 0.02596415 | K17: =(I17-E17)/E17 -> 0.015164527
A18: รวม | B18: =SUM(B5:B16) -> 1128 | C18: =SUM(C5:C16) -> 5523 | D18: =SUM(D5:D16) -> 44184 | E18: =SUM(E5:E16) -> 58.755319 | F18: =SUM(F5:F16) -> 1140 | G18: =SUM(G5:G16) -> 5666.4 | H18: =SUM(H5:H16) -> 45331.2 | I18: =SUM(I5:I16) -> 59.646316 | J18: =(G18-C18)/C18 -> 0.02596415 | K18: =(I18-E18)/E18 -> 0.015164527
A43: สรุปปริมาณการใช้น้ำ 1. ปริมาณน้ำสะสมตั้งแต่เดือน มกราคม ถึง ธันวาคม ปี 2567 เท่ากับ 5,666.40 หน่วย ลดลงจาก ปี 2566 ในช่วงเวลาเดียวกัน เท่ากับ 5,523.00 หน่วย คิดเป็น 2.6 % 2. ปริมาณน้ำต่อคนสะสมตั้งแต่เดือน มกราคม ถึง ธันวาคม ปี 2567 เท่ากับ 59.65 หน่วย ลดลงจาก ปี 2566 ในช่วงเวลาเดียวกัน เท่ากับ 58.76 หน่วย คิดเป็น 1.5 % 3. ปริมาณน้ำเฉลี่ยตั้งแต่เดือน มกราคม ถึง ธันวาคม ปี 2567 เท่ากับ 472.20 หน่วย ลดลงจาก ปี 2566 ในช่วงเวลาเดียวกัน เท่ากับ 60.25 หน่วย คิดเป็น 2.6 % 4. ปริมาณน้ำต่อคนเฉลี่ยตั้งแต่เดือน มกราคม ถึง ธันวาคม ปี 2567 เท่ากับ 4.97 หน่วย ลดลงจาก ปี 2566 ในช่วงเวลาเดียวกัน เท่ากับ 4.90 หน่วย คิดเป็น 1.5 %
A48: การวิเคราะห์ข้อมูลและสาเหตุ (เป้าหมาย : การใช้น้ำลดลง 5% จากปี 2566)
A49: เดือนมกราคม 2567
A50: รายละเอียด : | B50: ผลการใช้น้ำ ประจำเดือน มกราคม 2567 พบว่า มีการใช้น้ำ 291.00 หน่วย คิดเป็นเงิน 2,328.00 บาท มีปริมาณการใช้น้ำ 3.06 หน่วย/คน เมื่อเทียบกับปี 2566 ลดลง -31.0%
A51: วิเคราะห์สาเหตุ : | C51: เนื่องจากบุคคลากรให้ความร่วมมือในการปิดน้ำทุกครั้งเมื่อใช้เสร็จ และช่วยกันสังเกตหากมีจุดที่น้ำรั่วไหลจะทำการแจ้งผู้ดูแลอาคารทันที
A52: แนวทางจัดการ : | C52: ทำมาตรการจุดรับแจ้งน้ำรั่ว ตรวจมิเตอร์รายสัปดาห์ และรณรงค์การใช้น้ำอย่างประหยัด
A53: เดือนกุมภาพันธ์ 2567
A54: รายละเอียด : | B54: ผลการใช้น้ำ ประจำเดือน กุมภาพันธ์ 2567 พบว่า มีการใช้น้ำ 467.30 หน่วย คิดเป็นเงิน 3,738.40 บาท มีปริมาณการใช้น้ำ 4.92 หน่วย/คน เมื่อเทียบกับปี 2566 เพิ่มขึ้น 18.0%
A55: วิเคราะห์สาเหตุ : | C55: เนื่องจากมีก๊อกน้ำบริเวณห้องแลปชั้น2 แตก
A56: แนวทางจัดการ : | C56: กำหนดมาตรการการประหยัดน้ำเพิ่มมากขึ้น และให้บุคคลากรหมั่นตรวจเช็คก๊อกน้ำ และวาล์วน้ำ
A57: เดือนมีนาคม 2567
A58: รายละเอียด : | B58: ผลการใช้น้ำ ประจำเดือน มีนาคม 2567 พบว่า มีการใช้น้ำ 507.60 หน่วย คิดเป็นเงิน 4,060.80 บาท มีปริมาณการใช้น้ำ 5.34 หน่วย/คน เมื่อเทียบกับปี 2566 ลดลง 34.6%
A59: วิเคราะห์สาเหตุ : | C59: เนื่องจากบุคคลากรให้ความร่วมมือในการปิดน้ำทุกครั้งเมื่อใช้เสร็จ และช่วยกันสังเกตหากมีจุดที่น้ำรั่วไหลจะทำการแจ้งผู้ดูแลอาคารทันที
A60: แนวทางจัดการ : | C60: ทำมาตรการจุดรับแจ้งน้ำรั่ว ตรวจมิเตอร์รายสัปดาห์ และรณรงค์ให้บุคลากรใช้น้ำอย่างประหยัด
A61: เดือนเมษายน 2567
A62: รายละเอียด : | C62: ผลการใช้น้ำ ประจำเดือน เมษายน 2567 พบว่า มีการใช้น้ำ 452.30 หน่วย คิดเป็นเงิน 3,618.40 บาท มีปริมาณการใช้น้ำ 4.6 หน่วย/คน เมื่อเทียบกับปี 2566 ลดลง 17.5%
A63: วิเคราะห์สาเหตุ : | C63: เนื่องจากบุคคลากรให้ความร่วมมือในการปิดน้ำทุกครั้งเมื่อใช้เสร็จ และช่วยกันสังเกตหากมีจุดที่น้ำรั่วไหลจะทำการแจ้งผู้ดูแลอาคารทันที และตรงกลับวันหยุดยาว
A64: แนวทางจัดการ : | C64: ก่อนวันหยุดยาวให้ทำประกาศแจ้งให้บุคลากรทำการปิดวาล์วโซนที่ไม่จำเป็น/ตรวจรั่วก่อนปิดอาคาร เพื่อไม่ให้เกิดการรั่วไหลช่วงไม่มีคน
A65: เดือนพฤษภาคม 2567
A66: รายละเอียด : | C66: ผลการใช้น้ำ ประจำเดือน พฤษภาคม 2567 พบว่า มีการใช้น้ำ 408.70 หน่วย คิดเป็นเงิน 3,269.60 บาท มีปริมาณการใช้น้ำ 4.30 หน่วย/คน เมื่อเทียบกับปี 2566 ลดลง 0.6%
A67: วิเคราะห์สาเหตุ : | C67: เนื่องจากบุคคลากรให้ความร่วมมือในการปิดน้ำทุกครั้งเมื่อใช้เสร็จ และช่วยกันสังเกตหากมีจุดที่น้ำรั่วไหลจะทำการแจ้งผู้ดูแลอาคารทันที
A68: แนวทางจัดการ : | C68: ทำมาตรการจุดรับแจ้งน้ำรั่ว ตรวจมิเตอร์รายสัปดาห์ และรณรงค์ให้บุคลากรใช้น้ำอย่างประหยัด
...

Sheet 2568
K1: แบบฟอร์ม 3.2(1)
A2: บันทึกปริมาณการใช้น้ำ
A3: เดือน | B3: ปริมาณการใช้น้ำปี 2567 | F3: ปริมาณการใช้น้ำปี 2568 | J3: ร้อยละปริมาณการใช้น้ำ | M3: ป้อนข้อมูลตรงนี้
B4: จำนวนคน | C4: (ลบ.ม.) ปี2567 | D4: ค่าน้ำ/เดือน (บาท) | E4: (ลบ.ม./คน) ปี2567 | F4: จำนวนคน | G4: (ลบ.ม.) ปี 2568 | H4: ค่าน้ำ/เดือน (บาท) | I4: (ลบ.ม./คน)ปี 2568 | J4: (ลบ.ม.)ปี2568 | K4: (ลบ.ม./คน)ปี2568 | N4: ข้อมูล1(หลัง) | O4: ข้อมูล2(ก่อน)
A5: ม.ค. | B5: 389 | C5: 291 | D5: 2328 | E5: =C5/B5 -> 0.74807198 | F5: 705 | G5: =P5 -> 939 | H5: =G5*8 -> 7512 | I5: =G5/F5 -> 1.3319149 | J5: =(G5-C5)/C5 -> 2.2268041 | K5: =(I5-E5)/E5 -> 0.78046355 | M5: มกราคม | N5: 278389.3 | O5: 277450.3 | P5: =N5-O5 -> 939
A6: ก.พ. | B6: 874 | C6: 467.3 | D6: 3738.4 | E6: =C6/B6 -> 0.53466819 | F6: 1240 | G6: =P6 -> 447.5 | H6: =G6*8 -> 3580 | I6: =G6/F6 -> 0.3608871 | J6: =(G6-C6)/C6 -> -0.042371068 | K6: =(I6-E6)/E6 -> -0.32502606 | M6: กุมภาพันธ์ | N6: 278836.8 | O6: 278389.3 | P6: =N6-O6 -> 447.5
A7: มี.ค. | B7: 1374 | C7: 507.6 | D7: 4060.8 | E7: =C7/B7 -> 0.36943231 | F7: 1420 | G7: =P7 -> 555 | H7: =G7*8 -> 4440 | I7: =G7/F7 -> 0.39084507 | J7: =(G7-C7)/C7 -> 0.093380615 | K7: =(I7-E7)/E7 -> 0.057961243 | M7: มีนาคม | N7: 279391.8 | O7: 278836.8 | P7: =N7-O7 -> 555
A8: เม.ย. | B8: 684 | C8: 452.3 | D8: 3618.4 | E8: =C8/B8 -> 0.66125731 | F8: 640 | G8: =P8 -> 594.6 | H8: =G8*8 -> 4756.8 | I8: =G8/F8 -> 0.9290625 | J8: =(G8-C8)/C8 -> 0.31461419 | K8: =(I8-E8)/E8 -> 0.40499392 | M8: เมษายน | N8: 279986.4 | O8: 279391.8 | P8: =N8-O8 -> 594.6
A9: พ.ค. | B9: 824 | C9: 408.7 | D9: 3269.6 | E9: =C9/B9 -> 0.49599515 | F9: 790 | G9: =P9 -> 697.3 | H9: =G9*8 -> 5578.4 | I9: =G9/F9 -> 0.88265823 | J9: =(G9-C9)/C9 -> 0.70614142 | K9: =(I9-E9)/E9 -> 0.7795703 | M9: พฤษภาคม | N9: 280683.7 | O9: 279986.4 | P9: =N9-O9 -> 697.3
A10: มิ.ย. | B10: 1289 | C10: 369 | D10: 2952 | E10: =C10/B10 -> 0.28626843 | F10: 2050 | G10: =P10 -> 662.7 | H10: =G10*8 -> 5301.6 | I10: =G10/F10 -> 0.32326829 | J10: =(G10-C10)/C10 -> 0.79593496 | K10: =(I10-E10)/E10 -> 0.12924886 | M10: มิถุนายน | N10: 281346.4 | O10: 280683.7 | P10: =N10-O10 -> 662.7
A11: ก.ค. | B11: 1824 | C11: 462.1 | D11: 3696.8 | E11: =C11/B11 -> 0.2533443 | F11: 1305 | G11: =P11 -> 642.7 | H11: =G11*8 -> 5141.6 | I11: =G11/F11 -> 0.49249042 | J11: =(G11-C11)/C11 -> 0.3908245 | K11: =(I11-E11)/E11 -> 0.943957 | M11: กรกฎาคม | N11: 281989.1 | O11: 281346.4 | P11: =N11-O11 -> 642.7
A12: ส.ค. | B12: 1859 | C12: 348.6 | D12: 2788.8 | E12: =C12/B12 -> 0.18752017 | F12: 1375 | G12: =P12 -> 696.5 | H12: =G12*8 -> 5572 | I12: =G12/F12 -> 0.50654545 | J12: =(G12-C12)/C12 -> 0.99799197 | K12: =(I12-E12)/E12 -> 1.7012851 | M12: สิงหาคม | N12: 282685.6 | O12: 281989.1 | P12: =N12-O12 -> 696.5
A13: ก.ย. | B13: 3184 | C13: 355.5 | D13: 2844 | E13: =C13/B13 -> 0.11165201 | F13: 1245 | G13: =P13 -> 734.1 | H13: =G13*8 -> 5872.8 | I13: =G13/F13 -> 0.58963855 | J13: =(G13-C13)/C13 -> 1.0649789 | K13: =(I13-E13)/E13 -> 4.2810384 | M13: กันยายน | N13: 283419.7 | O13: 282685.6 | P13: =N13-O13 -> 734.1
A14: ต.ค. | B14: 1084 | C14: 463.6 | D14: 3708.8 | E14: =C14/B14 -> 0.42767528 | F14: 1010 | G14: =P14 -> 599.4 | H14: =G14*8 -> 4795.2 | I14: =G14/F14 -> 0.59346535 | J14: =(G14-C14)/C14 -> 0.29292494 | K14: =(I14-E14)/E14 -> 0.38765409 | M14: ตุลาคม | N14: 284019.1 | O14: 283419.7 | P14: =N14-O14 -> 599.4
A15: พ.ย. | B15: 1049 | C15: 508.1 | D15: 4064.8 | E15: =C15/B15 -> 0.48436606 | F15: 815 | G15: =P15 -> 840.6 | H15: =G15*8 -> 6724.8 | I15: =G15/F15 -> 1.031411 | J15: =(G15-C15)/C15 -> 0.65439874 | K15: =(I15-E15)/E15 -> 1.129404 | M15: พฤศจิกายน | N15: 284859.7 | O15: 284019.1 | P15: =N15-O15 -> 840.6
A16: ธ.ค. | B16: 959 | C16: 1032.6 | D16: 8260.8 | E16: =C16/B16 -> 1.0767466 | F16: 940 | G16: =P16 -> 928.1 | H16: =G16*8 -> 7424.8 | I16: =G16/F16 -> 0.98734043 | J16: =(G16-C16)/C16 -> -0.10120085 | K16: =(I16-E16)/E16 -> -0.083033635 | M16: ธันวาคม | N16: 285787.8 | O16: 284859.7 | P16: =N16-O16 -> 928.1
A17: เฉลี่ย | B17: =AVERAGE(B5:B16) -> 1282.75 | C17: =AVERAGE(C5:C16) -> 472.2 | D17: =AVERAGE(D5:D16) -> 3777.6 | E17: =AVERAGE(E5:E16) -> 0.46974982 | F17: =AVERAGE(F5:F16) -> 1127.9167 | G17: =AVERAGE(G5:G16) -> 694.79167 | H17: =AVERAGE(H5:H16) -> 5558.3333 | I17: =G17/F17 -> 0.61599557 | J17: =(G17-C17)/C17 -> 0.47139277 | K17: =(I17-E17)/E17 -> 0.31132689
A18: รวม | B18: =SUM(B5:B16) -> 15393 | C18: =SUM(C5:C16) -> 5666.4 | D18: =SUM(D5:D16) -> 45331.2 | E18: =SUM(E5:E16) -> 5.6369978 | F18: =SUM(F5:F16) -> 13535 | G18: =SUM(G5:G16) -> 8337.5 | H18: =SUM(H5:H16) -> 66700 | I18: =SUM(I5:I16) -> 8.4195273 | J18: =(G18-C18)/C18 -> 0.47139277 | K18: =(I18-E18)/E18 -> 0.49361906
A43: สรุปปริมาณการใช้น้ำ 1. ปริมาณน้ำสะสมตั้งแต่เดือน มกราคม ถึง ธันวาคมปี 2568 เท่ากับ 8,337.50 หน่วย เพิ่มขึ้น จาก ปี 2567 ในช่วงเวลาเดียวกัน เท่ากับ 5,666.40 หน่วย คิดเป็น 47.1 % 2. ปริมาณน้ำต่อคนสะสมตั้งแต่เดือน มกราคม ถึงธันวาคม ปี 2568 เท่ากับ 87.76 หน่วย เพิ่มขึ้น จาก ปี 2567 ในช่วงเวลาเดียวกัน เท่ากับ 59.65 หน่วย คิดเป็น 47.1 % 3. ปริมาณน้ำเฉลี่ยตั้งแต่เดือน มกราคม ถึง ธันวาคม ปี 2568 เท่ากับ 59.65 หน่วย เพิ่มขึ้น จาก ปี 2567 ในช่วงเวลาเดียวกัน เท่ากับ 87.76 หน่วย คิดเป็น 47.1 % 4. ปริมาณน้ำต่อคนเฉลี่ยตั้งแต่เดือน มกราคม ถึง ธันวาคม ปี 2568 เท่ากับ 7.31 หน่วย เพิ่มขึ้น จาก ปี 2567 ในช่วงเวลาเดียวกัน เท่ากับ 4.97 หน่วย คิดเป็น 47.1 %
A50: การวิเคราะห์ข้อมูลและสาเหตุ (เป้าหมาย : การใช้น้ำลดลง 1% จากปี 2568)
A51: เดือนมกราคม 2568
A52: รายละเอียด : | B52: ผลการใช้น้ำ ประจำเดือน มกราคม 2568 พบว่า มีการใช้น้ำ 939.00 หน่วย คิดเป็นเงิน 7,512.00 บาท มีปริมาณการใช้น้ำ 9.88 หน่วย/คน เมื่อเทียบกับปี 2567 เพิ่มขึ้น 222.%
A53: วิเคราะห์สาเหตุ : | C53: เนื่องจากมีบุคลากรและนักศึกษามาใช้ห้องบริการห้องประชุมจำนวนมาก และมีน้ำรั่วซึมบริเวณห้องปฏิบัติการชั้น2 แตก พร้อมทั้งมีการปลูกต้นไม้รอบอาคาร
A54: แนวทางจัดการ : | C54: ทำมาตรการจุดรับแจ้งน้ำรั่ว ตรวจมิเตอร์รายสัปดาห์ และรณรงค์การใช้น้ำอย่างประหยัด
A55: เดือนกุมภาพันธ์ 2568
A56: รายละเอียด : | B56: ผลการใช้น้ำ ประจำเดือน กุมภาพันธ์ 2568 พบว่า มีการใช้น้ำ 447.50 หน่วย คิดเป็นเงิน 3,580.00 บาท มีปริมาณการใช้น้ำ 4.71 หน่วย/คน เมื่อเทียบกับปี 2567 ลดลง -4.2%
A57: วิเคราะห์สาเหตุ : | C57: น้ำที่รั่วซึมบริเวณห้องปฏิบัติการชั้น 2 ซ่อมแซมเรียบร้อยแล้วบุคคลากรมีพฤติกรรมการใช้น้ำประหยัดน้ำ และมีมาตรฐานการให้ตัวแทนแต่ละชั้นตรวจเช็คก๊อกน้ำก่อนกลับบ้าน
A58: แนวทางจัดการ : | B58: ทำมาตรการจุดรับแจ้งน้ำรั่ว ตรวจมิเตอร์รายสัปดาห์ และรณรงค์การใช้น้ำอย่างประหยัด
A59: เดือนมีนาคม 2568
A60: รายละเอียด : | B60: ผลการใช้น้ำ ประจำเดือน มีนาคม 2568 พบว่า มีการใช้น้ำ 555.00 หน่วย คิดเป็นเงิน 4,440.00 บาท มีปริมาณการใช้น้ำ 5.84 หน่วย/คน เมื่อเทียบกับปี 2567 เพิ่มขึ้น 9.3%
A61: วิเคราะห์สาเหตุ : | C61: เนื่องจากมีบุคลากรและนักศึกษามาใช้ห้องบริการห้องประชุม อีกทั้งมีการใช้น้ำนอกอาคารต่อเนื่อง เช่น รดน้ำต้นไม้ หรือมีรั่วเล็ก ๆ ที่ไม่สามารถตรวจพบได้ตาเปล่า
A62: แนวทางจัดการ : | C62: ตรวจสุขภัณฑ์ที่เสื่อมสภาพ ทำมาตรการจุดรับแจ้งน้ำรั่ว และรณรงค์การใช้น้ำอย่างประหยัด
A63: เดือนเมษายน 2568
A64: รายละเอียด : | C64: ผลการใช้น้ำ ประจำเดือน เมษายน 2568 พบว่า มีการใช้น้ำ 594.60 หน่วย คิดเป็นเงิน 4,756.80 บาท มีปริมาณการใช้น้ำ 6.26 หน่วย/คน เมื่อเทียบกับปี 2567 เพิ่มขึ้น 31.5%
A65: วิเคราะห์สาเหตุ : | C65: การใช้น้ำเพิ่มขึ้นต่อเนื่องจำนวนผู้ใช้อาคารมากขึ้น รวมถึงพฤติกรรมการใช้น้ำที่ไม่ประหยัดของบุคคลกรในอาคาร หรือมาตรการควบคุมยังไม่เข้มพอ รวมถึงมีการรั่วไหลของระบบท่อประปาบริเวณนอกอาคารโดยที่ผู้ใช้อาคารอาจไม่สังเกตเห็น
A66: แนวทางจัดการ : | C66: เพิ่มความถี่การตรวจรั่วรายสัปดาห์ และมาตรการพฤติกรรม พร้อมทั้งป้ายเตือน ผู้รับผิดชอบปิดวาล์วแต่ละโซน
A67: เดือนพฤษภาคม 2568
A68: รายละเอียด : | C68: ผลการใช้น้ำ ประจำเดือน พฤษภาคม 2568 พบว่า มีการใช้น้ำ 697.30 หน่วย คิดเป็นเงิน 5,578.40 บาท มีปริมาณการใช้น้ำ 7.34 หน่วย/คน เมื่อเทียบกับปี 2567 เพิ่มขึ้น 70.6%
A69: วิเคราะห์สาเหตุ : | C69: การใช้น้ำเพิ่มขึ้นต่อเนื่องจำนวนผู้ใช้อาคารมากขึ้นกิจกรรมมากขึ้นจากกิจกรรมอบรมสัมมนา พฤติกรรมการใช้น้ำที่ไม่ประหยัดของบุคคลกรและเกิดการรั่วของระบบปะปา ชักโครกไหลตลอด รวมถึงการรั้วของท่อปะปาใต้อาคารที่ตรวจพบภายหลัง
A70: แนวทางจัดการ : | C70: ตรวจสุขภัณฑ์ทุกห้องน้ำแบบเช็คลิสต์ ทำการทดสอบปิดวาล์วเป็นโซนนอกเวลางานเพื่อหาวงจรรั่ว รวมถึงทำมาตรการจุดรับแจ้งน้ำรั่ว และรณรงค์การใช้น้ำอย่างประหยัด
...

Sheet 2569
K1: แบบฟอร์ม 3.1(1)
A2: บันทึกปริมาณการใช้น้ำ
A3: เดือน | B3: ปริมาณการใช้น้ำปี 2568 | F3: ปริมาณการใช้น้ำปี 2569 | J3: ร้อยละปริมาณการใช้น้ำ | M3: ป้อนข้อมูลตรงนี้
B4: จำนวนคน | C4: (ลบ.ม.)ปี2568 | D4: ค่าน้ำ/เดือน (บาท) | E4: (ลบ.ม./คน) ปี2568 | F4: จำนวนคน | G4: (ลบ.ม) ปี 2569 | H4: ค่าน้ำ/เดือน (บาท) | I4: (ลบ.ม./คน) ปี 2569 | J4: (ลบ.ม.)ปี2569 | K4: (ลบ.ม./คน)ปี2569 | N4: ข้อมูล1(หลัง) | O4: ข้อมูล2(ก่อน) | P4: หน่วย
A5: ม.ค. | B5: 705 | C5: ='2568'!G5 -> 939 | D5: =C5*8 -> 7512 | E5: =C5/B5 -> 1.3319149 | G5: =P5 -> 1098.4 | I5: =G5/F5 -> #DIV/0! | J5: =(G5-C5)/C5 -> 0.16975506 | K5: =(I5-E5)/E5 -> #DIV/0! | M5: มกราคม | N5: 286886.2 | O5: 285787.8 | P5: =N5-O5 -> 1098.4
A6: ก.พ. | B6: 1240 | C6: ='2568'!G6 -> 447.5 | D6: =C6*8 -> 3580 | E6: =C6/B6 -> 0.3608871 | G6: =P6 -> 944.6 | I6: =G6/F6 -> #DIV/0! | J6: =(G6-C6)/C6 -> 1.110838 | K6: =(I6-E6)/E6 -> #DIV/0! | M6: กุมภาพันธ์ | N6: 287830.8 | O6: 286886.2 | P6: =N6-O6 -> 944.6
A7: มี.ค. | B7: 1420 | C7: ='2568'!G7 -> 555 | D7: =C7*8 -> 4440 | E7: =C7/B7 -> 0.39084507 | G7: =P7 -> 909.7 | I7: =G7/F7 -> #DIV/0! | J7: =(G7-C7)/C7 -> 0.6390991 | K7: =(I7-E7)/E7 -> #DIV/0! | M7: มีนาคม | N7: 288740.5 | O7: 287830.8 | P7: =N7-O7 -> 909.7 | S7: 288740.5
A8: เม.ย. | B8: 640 | C8: ='2568'!G8 -> 594.6 | D8: =C8*8 -> 4756.8 | E8: =C8/B8 -> 0.9290625 | G8: =P8 -> 858.3 | I8: =G8/F8 -> #DIV/0! | J8: =(G8-C8)/C8 -> 0.44349142 | K8: =(I8-E8)/E8 -> #DIV/0! | M8: เมษายน | N8: 289598.8 | O8: 288740.5 | P8: =N8-O8 -> 858.3
A9: พ.ค. | B9: 790 | C9: ='2568'!G9 -> 697.3 | D9: =C9*8 -> 5578.4 | E9: =C9/B9 -> 0.88265823 | G9: =P9 -> 539.96 | I9: =G9/F9 -> #DIV/0! | J9: =(G9-C9)/C9 -> -0.22564176 | K9: =(I9-E9)/E9 -> #DIV/0! | M9: พฤษภาคม | N9: 1188.43 | O9: 648.47 | P9: =N9-O9 -> 539.96
A10: มิ.ย. | B10: 2050 | C10: ='2568'!G10 -> 662.7 | D10: =C10*8 -> 5301.6 | E10: =C10/B10 -> 0.32326829 | G10: =P10 -> 574.71 | I10: =G10/F10 -> #DIV/0! | J10: =(G10-C10)/C10 -> -0.13277501 | K10: =(I10-E10)/E10 -> #DIV/0! | M10: มิถุนายน | N10: 1763.14 | O10: 1188.43 | P10: =N10-O10 -> 574.71
A11: ก.ค. | B11: 1305 | C11: ='2568'!G11 -> 642.7 | D11: =C11*8 -> 5141.6 | E11: =C11/B11 -> 0.49249042 | G11: =P11 -> 646.36 | I11: =G11/F11 -> #DIV/0! | J11: =(G11-C11)/C11 -> 0.0056947254 | K11: =(I11-E11)/E11 -> #DIV/0! | M11: กรกฎาคม | N11: 2409.5 | O11: 1763.14 | P11: =N11-O11 -> 646.36
A12: ส.ค. | B12: 1375 | C12: ='2568'!G12 -> 696.5 | D12: =C12*8 -> 5572 | E12: =C12/B12 -> 0.50654545 | G12: =P12 -> 0 | I12: =G12/F12 -> #DIV/0! | J12: =(G12-C12)/C12 -> -1 | K12: =(I12-E12)/E12 -> #DIV/0! | M12: สิงหาคม | P12: =N12-O12 -> 0
A13: ก.ย. | B13: 1245 | C13: ='2568'!G13 -> 734.1 | D13: =C13*8 -> 5872.8 | E13: =C13/B13 -> 0.58963855 | G13: =P13 -> 0 | I13: =G13/F13 -> #DIV/0! | J13: =(G13-C13)/C13 -> -1 | K13: =(I13-E13)/E13 -> #DIV/0! | M13: กันยายน | P13: =N13-O13 -> 0
A14: ต.ค. | B14: 1010 | C14: ='2568'!G14 -> 599.4 | D14: =C14*8 -> 4795.2 | E14: =C14/B14 -> 0.59346535 | G14: =P14 -> 0 | I14: =G14/F14 -> #DIV/0! | J14: =(G14-C14)/C14 -> -1 | K14: =(I14-E14)/E14 -> #DIV/0! | M14: ตุลาคม | P14: =N14-O14 -> 0
A15: พ.ย. | B15: 815 | C15: ='2568'!G15 -> 840.6 | D15: =C15*8 -> 6724.8 | E15: =C15/B15 -> 1.031411 | G15: =P15 -> 0 | I15: =G15/F15 -> #DIV/0! | J15: =(G15-C15)/C15 -> -1 | K15: =(I15-E15)/E15 -> #DIV/0! | M15: พฤศจิกายน | P15: =N15-O15 -> 0
A16: ธ.ค. | B16: 940 | C16: ='2568'!G16 -> 928.1 | D16: =C16*8 -> 7424.8 | E16: =C16/B16 -> 0.98734043 | G16: =P16 -> 0 | I16: =G16/F16 -> #DIV/0! | J16: =(G16-C16)/C16 -> -1 | K16: =(I16-E16)/E16 -> #DIV/0! | M16: ธันวาคม | P16: =N16-O16 -> 0
A17: เฉลี่ย | B17: =AVERAGE(B5:B16) -> 1127.9167 | C17: =AVERAGE(C5:C16) -> 694.79167 | D17: =AVERAGE(D5:D16) -> 5558.3333 | E17: =AVERAGE(E5:E16) -> 0.70162728 | F17: =AVERAGE(F5:F16) -> #DIV/0! | G17: =AVERAGE(G5:G16) -> 464.33583 | H17: =AVERAGE(H5:H16) -> #DIV/0! | I17: =G17/F17 -> #DIV/0! | J17: =(G17-C17)/C17 -> -0.33169055 | K17: =(I17-E17)/E17 -> #DIV/0!
A18: รวม | B18: =SUM(B5:B16) -> 13535 | C18: =SUM(C5:C16) -> 8337.5 | D18: =SUM(D5:D16) -> 66700 | E18: =SUM(E5:E16) -> 8.4195273 | F18: =SUM(F5:F16) -> 0 | G18: =SUM(G5:G16) -> 5572.03 | H18: =SUM(H5:H16) -> 0 | I18: =SUM(I5:I16) -> #DIV/0! | J18: =(G18-C18)/C18 -> -0.33169055 | K18: =(I18-E18)/E18 -> #DIV/0!
A43: สรุปปริมาณการใช้น้ำ 1. การปริมาณน้ำสะสมตั้งแต่เดือน มกราคม ถึง ….............ปี 2569 เท่ากับ …......... ลบ.ม. ลดลงจาก ปี 25….ในช่วงเวลาเดียวกัน เท่ากับ …............. ลบ.ม. คิดเป็น …...... % 2. การปริมาณน้ำต่อคนสะสมตั้งแต่เดือน มกราคม ถึง ….............ปี 2569 เท่ากับ …......... ลบ.ม./คน ลดลงจาก ปี 25….ในช่วงเวลาเดียวกัน เท่ากับ …......... ลบ.ม./คน คิดเป็น …...... % 3. การปริมาณน้ำเฉลี่ยตั้งแต่เดือน มกราคม ถึง ….............ปี 2569 เท่ากับ …......... ลบ.ม. ลดลงจาก ปี 25….ในช่วงเวลาเดียวกัน เท่ากับ …............. ลบ.ม. คิดเป็น …...... % 4. การปริมาณน้ำต่อคนเฉลี่ยตั้งแต่เดือน มกราคม ถึง ….............ปี 2569 เท่ากับ …......... ลบ.ม./คน ลดลงจาก ปี 25….ในช่วงเวลาเดียวกัน เท่ากับ ….......... ลบ.ม./คน คิดเป็น …...... %
E48: บรรลุเป้าหมาย | H48: ไม่บรรลุเป้าหมาย
A49: การวิเคราะห์ข้อมูลและสาเหตุ (เป้าหมาย 2569 : การใช้น้ำลดลง …...........% จากปี 25…....)
A50: เดือนมกราคม 2569 | D50: บรรลุเป้าหมาย | G50: ไม่บรรลุเป้าหมาย
A51: รายละเอียด :
A52: วิเคราะห์สาเหตุ :
A53: แนวทางจัดการ :
A54: เดือนกุมภาพันธ์ 2569 | D54: บรรลุเป้าหมาย | G54: ไม่บรรลุเป้าหมาย
A55: รายละเอียด :
A56: วิเคราะห์สาเหตุ :
A57: แนวทางจัดการ :
A58: เดือนมีนาคม 2569 | D58: บรรลุเป้าหมาย | G58: ไม่บรรลุเป้าหมาย
A59: รายละเอียด :
A60: วิเคราะห์สาเหตุ :
A61: แนวทางจัดการ :
A62: เดือนเมษายน 2569 | D62: บรรลุเป้าหมาย | G62: ไม่บรรลุเป้าหมาย
A63: รายละเอียด :
A64: วิเคราะห์สาเหตุ :
A65: แนวทางจัดการ :
A66: เดือนพฤษภาคม 2569 | D66: บรรลุเป้าหมาย | G66: ไม่บรรลุเป้าหมาย
A67: รายละเอียด :
A68: วิเคราะห์สาเหตุ :
...

Sheet น้ำทิ้งเครื่องปรับอากาศ
A1: ตารางบันทึกปริมาณน้ำเครื่องปรับอากาศ เดือน มกราคม 2567
A3: ที่ | B3: วัน/เดือน/ปี | C3: เวลา | D3: ปริมาณน้ำที่วัดได้ | E3: ผู้บันทึก | F3: หมายเหตุ
D4: (มิลลิลิตร)
A5: 1 | B5: 2 มกราคม 67 | C5: 16.00 น.
A6: 2 | B6: 3 มกราคม 67 | C6: 16.00 น.
A7: 3 | B7: 4 มกราคม 67 | C7: 16.00 น.
A8: 4 | B8: 5 มกราคม 67 | C8: 16.00 น.
A9: 5 | B9: 8 มกราคม 67 | C9: 16.00 น.
A10: 6 | B10: 9 มกราคม 67 | C10: 16.00 น.
A11: 7 | B11: 10 มกราคม 67 | C11: 16.00 น.
A12: 8 | B12: 11 มกราคม 67 | C12: 16.00 น.
A13: 9 | B13: 12 มกราคม 67 | C13: 16.00 น.
A14: 10 | B14: 15 มกราคม 67 | C14: 16.00 น.
A15: 11 | B15: 16 มกราคม 67 | C15: 16.00 น.
A16: 12 | B16: 17 มกราคม 67 | C16: 16.00 น.
... A26: 22 | B26: 31 มกราคม 67 | C26: 16.00 น.
D29: .................................................
D30: (....................................)
D31: ผู้ตรวจสอบ
A33: ตารางบันทึกปริมาณน้ำเครื่องปรับอากาศ เดือน กุมภาพันธ์ 2567
A35: ที่ | B35: วัน/เดือน/ปี | C35: เวลา | D35: ปริมาณน้ำที่วัดได้ | E35: ผู้บันทึก | F35: หมายเหตุ
D36: (มิลลิลิตร)
A37: 1 | B37: 1 กุมภาพันธ์ 67 | C37: 16.00 น.
A38: 2 | B38: 2 กุมภาพันธ์ 67 | C38: 16.00 น.
A39: 3 | B39: 5 กุมภาพันธ์ 67 | C39: 16.00 น.
A40: 4 | B40: 6 กุมภาพันธ์ 67 | C40: 16.00 น.
A41: 5 | B41: 7 กุมภาพันธ์ 67 | C41: 16.00 น.
A42: 6 | B42: 8 กุมภาพันธ์ 67 | C42: 16.00 น.
A43: 7 | B43: 9 กุมภาพันธ์ 67 | C43: 16.00 น.
A44: 8 | B44: 12 กุมภาพันธ์ 67 | C44: 16.00 น.
A45: 9 | B45: 13 กุมภาพันธ์ 67 | C45: 16.00 น.
A46: 10 | B46: 14 กุมภาพันธ์ 67 | C46: 16.00 น.
A47: 11 | B47: 15 กุมภาพันธ์ 67 | C47: 16.00 น.
A48: 12 | B48: 16 กุมภาพันธ์ 67 | C48: 16.00 น.
... A56: 20 | B56: 29 กุมภาพันธ์ 67 | C56: 16.00 น.
D59: .................................................
D60: (....................................)
D61: ผู้ตรวจสอบ
A63: ตารางบันทึกปริมาณน้ำเครื่องปรับอากาศ เดือน มีนาคม 2567
A65: ที่ | B65: วัน/เดือน/ปี | C65: เวลา | D65: ปริมาณน้ำที่วัดได้ | E65: ผู้บันทึก | F65: หมายเหตุ
...
